[2022-07-06 09:45:19 +0530] [4085613] [DEBUG] Current configuration:
  config: gunicorn_conf.py
  wsgi_app: None
  bind: ['unix:/home/admin/projectDir/mlapi/gunicorn.sock']
  backlog: 2048
  workers: 7
  worker_class: uvicorn.workers.UvicornWorker
  threads: 1
  worker_connections: 1000
  max_requests: 0
  max_requests_jitter: 0
  timeout: 30
  graceful_timeout: 30
  keepalive: 2
  limit_request_line: 4094
  limit_request_fields: 100
  limit_request_field_size: 8190
  reload: False
  reload_engine: auto
  reload_extra_files: []
  spew: False
  check_config: False
  print_config: False
  preload_app: False
  sendfile: None
  reuse_port: False
  chdir: /home/admin/projectDir/mlapi
  daemon: False
  raw_env: []
  pidfile: None
  worker_tmp_dir: None
  user: 0
  group: 33
  umask: 0
  initgroups: False
  tmp_upload_dir: None
  secure_scheme_headers: {'X-FORWARDED-PROTOCOL': 'ssl', 'X-FORWARDED-PROTO': 'https', 'X-FORWARDED-SSL': 'on'}
  forwarded_allow_ips: ['127.0.0.1']
  accesslog: /home/admin/projectDir/mlapi/access_log
  disable_redirect_access_to_syslog: False
  access_log_format: %(h)s %(l)s %(u)s %(t)s "%(r)s" %(s)s %(b)s "%(f)s" "%(a)s"
  errorlog: /home/admin/projectDir/mlapi/error_log
  loglevel: debug
  capture_output: False
  logger_class: gunicorn.glogging.Logger
  logconfig: None
  logconfig_dict: {}
  syslog_addr: udp://localhost:514
  syslog: False
  syslog_prefix: None
  syslog_facility: user
  enable_stdio_inheritance: False
  statsd_host: None
  dogstatsd_tags: 
  statsd_prefix: 
  proc_name: None
  default_proc_name: app:app
  pythonpath: None
  paste: None
  on_starting: <function OnStarting.on_starting at 0x7fa53fd65990>
  on_reload: <function OnReload.on_reload at 0x7fa53fd65ab0>
  when_ready: <function WhenReady.when_ready at 0x7fa53fd65bd0>
  pre_fork: <function Prefork.pre_fork at 0x7fa53fd65cf0>
  post_fork: <function Postfork.post_fork at 0x7fa53fd65e10>
  post_worker_init: <function PostWorkerInit.post_worker_init at 0x7fa53fd65f30>
  worker_int: <function WorkerInt.worker_int at 0x7fa53fd66050>
  worker_abort: <function WorkerAbort.worker_abort at 0x7fa53fd66170>
  pre_exec: <function PreExec.pre_exec at 0x7fa53fd66290>
  pre_request: <function PreRequest.pre_request at 0x7fa53fd663b0>
  post_request: <function PostRequest.post_request at 0x7fa53fd66440>
  child_exit: <function ChildExit.child_exit at 0x7fa53fd66560>
  worker_exit: <function WorkerExit.worker_exit at 0x7fa53fd66680>
  nworkers_changed: <function NumWorkersChanged.nworkers_changed at 0x7fa53fd667a0>
  on_exit: <function OnExit.on_exit at 0x7fa53fd668c0>
  proxy_protocol: False
  proxy_allow_ips: ['127.0.0.1']
  keyfile: None
  certfile: None
  ssl_version: 2
  cert_reqs: 0
  ca_certs: None
  suppress_ragged_eofs: True
  do_handshake_on_connect: False
  ciphers: None
  raw_paste_global_conf: []
  strip_header_spaces: False
[2022-07-06 09:45:19 +0530] [4085613] [INFO] Starting gunicorn 20.1.0
[2022-07-06 09:45:19 +0530] [4085613] [DEBUG] Arbiter booted
[2022-07-06 09:45:19 +0530] [4085613] [INFO] Listening at: unix:/home/admin/projectDir/mlapi/gunicorn.sock (4085613)
[2022-07-06 09:45:19 +0530] [4085613] [INFO] Using worker: uvicorn.workers.UvicornWorker
[2022-07-06 09:45:19 +0530] [4085629] [INFO] Booting worker with pid: 4085629
[2022-07-06 09:45:19 +0530] [4085629] [ERROR] Exception in worker process
Traceback (most recent call last):
  File "/root/anaconda3/envs/fastapi/lib/python3.10/site-packages/gunicorn/arbiter.py", line 589, in spawn_worker
    worker.init_process()
  File "/root/anaconda3/envs/fastapi/lib/python3.10/site-packages/uvicorn/workers.py", line 66, in init_process
    super(UvicornWorker, self).init_process()
  File "/root/anaconda3/envs/fastapi/lib/python3.10/site-packages/gunicorn/workers/base.py", line 134, in init_process
    self.load_wsgi()
  File "/root/anaconda3/envs/fastapi/lib/python3.10/site-packages/gunicorn/workers/base.py", line 146, in load_wsgi
    self.wsgi = self.app.wsgi()
  File "/root/anaconda3/envs/fastapi/lib/python3.10/site-packages/gunicorn/app/base.py", line 67, in wsgi
    self.callable = self.load()
  File "/root/anaconda3/envs/fastapi/lib/python3.10/site-packages/gunicorn/app/wsgiapp.py", line 58, in load
    return self.load_wsgiapp()
  File "/root/anaconda3/envs/fastapi/lib/python3.10/site-packages/gunicorn/app/wsgiapp.py", line 48, in load_wsgiapp
    return util.import_app(self.app_uri)
  File "/root/anaconda3/envs/fastapi/lib/python3.10/site-packages/gunicorn/util.py", line 359, in import_app
    mod = importlib.import_module(module)
  File "/root/anaconda3/envs/fastapi/lib/python3.10/importlib/__init__.py", line 126, in import_module
    return _bootstrap._gcd_import(name[level:], package, level)
  File "<frozen importlib._bootstrap>", line 1050, in _gcd_import
  File "<frozen importlib._bootstrap>", line 1027, in _find_and_load
  File "<frozen importlib._bootstrap>", line 1004, in _find_and_load_unlocked
ModuleNotFoundError: No module named 'app'
[2022-07-06 09:45:19 +0530] [4085630] [INFO] Booting worker with pid: 4085630
[2022-07-06 09:45:19 +0530] [4085629] [INFO] Worker exiting (pid: 4085629)
[2022-07-06 09:45:19 +0530] [4085630] [ERROR] Exception in worker process
Traceback (most recent call last):
  File "/root/anaconda3/envs/fastapi/lib/python3.10/site-packages/gunicorn/arbiter.py", line 589, in spawn_worker
    worker.init_process()
  File "/root/anaconda3/envs/fastapi/lib/python3.10/site-packages/uvicorn/workers.py", line 66, in init_process
    super(UvicornWorker, self).init_process()
  File "/root/anaconda3/envs/fastapi/lib/python3.10/site-packages/gunicorn/workers/base.py", line 134, in init_process
    self.load_wsgi()
  File "/root/anaconda3/envs/fastapi/lib/python3.10/site-packages/gunicorn/workers/base.py", line 146, in load_wsgi
    self.wsgi = self.app.wsgi()
  File "/root/anaconda3/envs/fastapi/lib/python3.10/site-packages/gunicorn/app/base.py", line 67, in wsgi
    self.callable = self.load()
  File "/root/anaconda3/envs/fastapi/lib/python3.10/site-packages/gunicorn/app/wsgiapp.py", line 58, in load
    return self.load_wsgiapp()
  File "/root/anaconda3/envs/fastapi/lib/python3.10/site-packages/gunicorn/app/wsgiapp.py", line 48, in load_wsgiapp
    return util.import_app(self.app_uri)
  File "/root/anaconda3/envs/fastapi/lib/python3.10/site-packages/gunicorn/util.py", line 359, in import_app
    mod = importlib.import_module(module)
  File "/root/anaconda3/envs/fastapi/lib/python3.10/importlib/__init__.py", line 126, in import_module
    return _bootstrap._gcd_import(name[level:], package, level)
  File "<frozen importlib._bootstrap>", line 1050, in _gcd_import
  File "<frozen importlib._bootstrap>", line 1027, in _find_and_load
  File "<frozen importlib._bootstrap>", line 1004, in _find_and_load_unlocked
ModuleNotFoundError: No module named 'app'
[2022-07-06 09:45:19 +0530] [4085630] [INFO] Worker exiting (pid: 4085630)
[2022-07-06 09:45:19 +0530] [4085631] [INFO] Booting worker with pid: 4085631
[2022-07-06 09:45:19 +0530] [4085631] [ERROR] Exception in worker process
Traceback (most recent call last):
  File "/root/anaconda3/envs/fastapi/lib/python3.10/site-packages/gunicorn/arbiter.py", line 589, in spawn_worker
    worker.init_process()
  File "/root/anaconda3/envs/fastapi/lib/python3.10/site-packages/uvicorn/workers.py", line 66, in init_process
    super(UvicornWorker, self).init_process()
  File "/root/anaconda3/envs/fastapi/lib/python3.10/site-packages/gunicorn/workers/base.py", line 134, in init_process
    self.load_wsgi()
  File "/root/anaconda3/envs/fastapi/lib/python3.10/site-packages/gunicorn/workers/base.py", line 146, in load_wsgi
    self.wsgi = self.app.wsgi()
  File "/root/anaconda3/envs/fastapi/lib/python3.10/site-packages/gunicorn/app/base.py", line 67, in wsgi
    self.callable = self.load()
  File "/root/anaconda3/envs/fastapi/lib/python3.10/site-packages/gunicorn/app/wsgiapp.py", line 58, in load
    return self.load_wsgiapp()
  File "/root/anaconda3/envs/fastapi/lib/python3.10/site-packages/gunicorn/app/wsgiapp.py", line 48, in load_wsgiapp
    return util.import_app(self.app_uri)
  File "/root/anaconda3/envs/fastapi/lib/python3.10/site-packages/gunicorn/util.py", line 359, in import_app
    mod = importlib.import_module(module)
  File "/root/anaconda3/envs/fastapi/lib/python3.10/importlib/__init__.py", line 126, in import_module
    return _bootstrap._gcd_import(name[level:], package, level)
  File "<frozen importlib._bootstrap>", line 1050, in _gcd_import
  File "<frozen importlib._bootstrap>", line 1027, in _find_and_load
  File "<frozen importlib._bootstrap>", line 1004, in _find_and_load_unlocked
ModuleNotFoundError: No module named 'app'
[2022-07-06 09:45:19 +0530] [4085631] [INFO] Worker exiting (pid: 4085631)
[2022-07-06 09:45:19 +0530] [4085632] [INFO] Booting worker with pid: 4085632
[2022-07-06 09:45:19 +0530] [4085633] [INFO] Booting worker with pid: 4085633
[2022-07-06 09:45:19 +0530] [4085613] [WARNING] Worker with pid 4085629 was terminated due to signal 15
[2022-07-06 09:45:19 +0530] [4085613] [WARNING] Worker with pid 4085631 was terminated due to signal 15
[2022-07-06 09:45:19 +0530] [4085632] [ERROR] Exception in worker process
Traceback (most recent call last):
  File "/root/anaconda3/envs/fastapi/lib/python3.10/site-packages/gunicorn/arbiter.py", line 589, in spawn_worker
    worker.init_process()
  File "/root/anaconda3/envs/fastapi/lib/python3.10/site-packages/uvicorn/workers.py", line 66, in init_process
    super(UvicornWorker, self).init_process()
  File "/root/anaconda3/envs/fastapi/lib/python3.10/site-packages/gunicorn/workers/base.py", line 134, in init_process
    self.load_wsgi()
  File "/root/anaconda3/envs/fastapi/lib/python3.10/site-packages/gunicorn/workers/base.py", line 146, in load_wsgi
    self.wsgi = self.app.wsgi()
  File "/root/anaconda3/envs/fastapi/lib/python3.10/site-packages/gunicorn/app/base.py", line 67, in wsgi
    self.callable = self.load()
  File "/root/anaconda3/envs/fastapi/lib/python3.10/site-packages/gunicorn/app/wsgiapp.py", line 58, in load
    return self.load_wsgiapp()
  File "/root/anaconda3/envs/fastapi/lib/python3.10/site-packages/gunicorn/app/wsgiapp.py", line 48, in load_wsgiapp
    return util.import_app(self.app_uri)
  File "/root/anaconda3/envs/fastapi/lib/python3.10/site-packages/gunicorn/util.py", line 359, in import_app
    mod = importlib.import_module(module)
  File "/root/anaconda3/envs/fastapi/lib/python3.10/importlib/__init__.py", line 126, in import_module
    return _bootstrap._gcd_import(name[level:], package, level)
  File "<frozen importlib._bootstrap>", line 1050, in _gcd_import
  File "<frozen importlib._bootstrap>", line 1027, in _find_and_load
  File "<frozen importlib._bootstrap>", line 1004, in _find_and_load_unlocked
ModuleNotFoundError: No module named 'app'
[2022-07-06 09:45:19 +0530] [4085632] [INFO] Worker exiting (pid: 4085632)
[2022-07-06 09:45:19 +0530] [4085633] [ERROR] Exception in worker process
Traceback (most recent call last):
  File "/root/anaconda3/envs/fastapi/lib/python3.10/site-packages/gunicorn/arbiter.py", line 589, in spawn_worker
    worker.init_process()
  File "/root/anaconda3/envs/fastapi/lib/python3.10/site-packages/uvicorn/workers.py", line 66, in init_process
    super(UvicornWorker, self).init_process()
  File "/root/anaconda3/envs/fastapi/lib/python3.10/site-packages/gunicorn/workers/base.py", line 134, in init_process
    self.load_wsgi()
  File "/root/anaconda3/envs/fastapi/lib/python3.10/site-packages/gunicorn/workers/base.py", line 146, in load_wsgi
    self.wsgi = self.app.wsgi()
  File "/root/anaconda3/envs/fastapi/lib/python3.10/site-packages/gunicorn/app/base.py", line 67, in wsgi
    self.callable = self.load()
  File "/root/anaconda3/envs/fastapi/lib/python3.10/site-packages/gunicorn/app/wsgiapp.py", line 58, in load
    return self.load_wsgiapp()
  File "/root/anaconda3/envs/fastapi/lib/python3.10/site-packages/gunicorn/app/wsgiapp.py", line 48, in load_wsgiapp
    return util.import_app(self.app_uri)
  File "/root/anaconda3/envs/fastapi/lib/python3.10/site-packages/gunicorn/util.py", line 359, in import_app
    mod = importlib.import_module(module)
  File "/root/anaconda3/envs/fastapi/lib/python3.10/importlib/__init__.py", line 126, in import_module
    return _bootstrap._gcd_import(name[level:], package, level)
  File "<frozen importlib._bootstrap>", line 1050, in _gcd_import
  File "<frozen importlib._bootstrap>", line 1027, in _find_and_load
  File "<frozen importlib._bootstrap>", line 1004, in _find_and_load_unlocked
ModuleNotFoundError: No module named 'app'
[2022-07-06 09:45:19 +0530] [4085633] [INFO] Worker exiting (pid: 4085633)
[2022-07-06 09:49:27 +0530] [4091245] [DEBUG] Current configuration:
  config: gunicorn_conf.py
  wsgi_app: None
  bind: ['unix:/home/admin/projectDir/mlapi/fastapi.sock']
  backlog: 2048
  workers: 7
  worker_class: uvicorn.workers.UvicornWorker
  threads: 1
  worker_connections: 1000
  max_requests: 0
  max_requests_jitter: 0
  timeout: 30
  graceful_timeout: 30
  keepalive: 2
  limit_request_line: 4094
  limit_request_fields: 100
  limit_request_field_size: 8190
  reload: False
  reload_engine: auto
  reload_extra_files: []
  spew: False
  check_config: False
  print_config: False
  preload_app: False
  sendfile: None
  reuse_port: False
  chdir: /home/admin/projectDir/mlapi
  daemon: False
  raw_env: []
  pidfile: None
  worker_tmp_dir: None
  user: 0
  group: 33
  umask: 0
  initgroups: False
  tmp_upload_dir: None
  secure_scheme_headers: {'X-FORWARDED-PROTOCOL': 'ssl', 'X-FORWARDED-PROTO': 'https', 'X-FORWARDED-SSL': 'on'}
  forwarded_allow_ips: ['127.0.0.1']
  accesslog: /home/admin/projectDir/mlapi/access_log
  disable_redirect_access_to_syslog: False
  access_log_format: %(h)s %(l)s %(u)s %(t)s "%(r)s" %(s)s %(b)s "%(f)s" "%(a)s"
  errorlog: /home/admin/projectDir/mlapi/error_log
  loglevel: debug
  capture_output: False
  logger_class: gunicorn.glogging.Logger
  logconfig: None
  logconfig_dict: {}
  syslog_addr: udp://localhost:514
  syslog: False
  syslog_prefix: None
  syslog_facility: user
  enable_stdio_inheritance: False
  statsd_host: None
  dogstatsd_tags: 
  statsd_prefix: 
  proc_name: None
  default_proc_name: app:app
  pythonpath: None
  paste: None
  on_starting: <function OnStarting.on_starting at 0x7fec416d1990>
  on_reload: <function OnReload.on_reload at 0x7fec416d1ab0>
  when_ready: <function WhenReady.when_ready at 0x7fec416d1bd0>
  pre_fork: <function Prefork.pre_fork at 0x7fec416d1cf0>
  post_fork: <function Postfork.post_fork at 0x7fec416d1e10>
  post_worker_init: <function PostWorkerInit.post_worker_init at 0x7fec416d1f30>
  worker_int: <function WorkerInt.worker_int at 0x7fec416d2050>
  worker_abort: <function WorkerAbort.worker_abort at 0x7fec416d2170>
  pre_exec: <function PreExec.pre_exec at 0x7fec416d2290>
  pre_request: <function PreRequest.pre_request at 0x7fec416d23b0>
  post_request: <function PostRequest.post_request at 0x7fec416d2440>
  child_exit: <function ChildExit.child_exit at 0x7fec416d2560>
  worker_exit: <function WorkerExit.worker_exit at 0x7fec416d2680>
  nworkers_changed: <function NumWorkersChanged.nworkers_changed at 0x7fec416d27a0>
  on_exit: <function OnExit.on_exit at 0x7fec416d28c0>
  proxy_protocol: False
  proxy_allow_ips: ['127.0.0.1']
  keyfile: None
  certfile: None
  ssl_version: 2
  cert_reqs: 0
  ca_certs: None
  suppress_ragged_eofs: True
  do_handshake_on_connect: False
  ciphers: None
  raw_paste_global_conf: []
  strip_header_spaces: False
[2022-07-06 09:49:27 +0530] [4091245] [INFO] Starting gunicorn 20.1.0
[2022-07-06 09:49:27 +0530] [4091245] [DEBUG] Arbiter booted
[2022-07-06 09:49:27 +0530] [4091245] [INFO] Listening at: unix:/home/admin/projectDir/mlapi/fastapi.sock (4091245)
[2022-07-06 09:49:27 +0530] [4091245] [INFO] Using worker: uvicorn.workers.UvicornWorker
[2022-07-06 09:49:27 +0530] [4091254] [INFO] Booting worker with pid: 4091254
[2022-07-06 09:49:27 +0530] [4091254] [ERROR] Exception in worker process
Traceback (most recent call last):
  File "/root/anaconda3/envs/fastapi/lib/python3.10/site-packages/gunicorn/arbiter.py", line 589, in spawn_worker
    worker.init_process()
  File "/root/anaconda3/envs/fastapi/lib/python3.10/site-packages/uvicorn/workers.py", line 66, in init_process
    super(UvicornWorker, self).init_process()
  File "/root/anaconda3/envs/fastapi/lib/python3.10/site-packages/gunicorn/workers/base.py", line 134, in init_process
    self.load_wsgi()
  File "/root/anaconda3/envs/fastapi/lib/python3.10/site-packages/gunicorn/workers/base.py", line 146, in load_wsgi
    self.wsgi = self.app.wsgi()
  File "/root/anaconda3/envs/fastapi/lib/python3.10/site-packages/gunicorn/app/base.py", line 67, in wsgi
    self.callable = self.load()
  File "/root/anaconda3/envs/fastapi/lib/python3.10/site-packages/gunicorn/app/wsgiapp.py", line 58, in load
    return self.load_wsgiapp()
  File "/root/anaconda3/envs/fastapi/lib/python3.10/site-packages/gunicorn/app/wsgiapp.py", line 48, in load_wsgiapp
    return util.import_app(self.app_uri)
  File "/root/anaconda3/envs/fastapi/lib/python3.10/site-packages/gunicorn/util.py", line 359, in import_app
    mod = importlib.import_module(module)
  File "/root/anaconda3/envs/fastapi/lib/python3.10/importlib/__init__.py", line 126, in import_module
    return _bootstrap._gcd_import(name[level:], package, level)
  File "<frozen importlib._bootstrap>", line 1050, in _gcd_import
  File "<frozen importlib._bootstrap>", line 1027, in _find_and_load
  File "<frozen importlib._bootstrap>", line 1004, in _find_and_load_unlocked
ModuleNotFoundError: No module named 'app'
[2022-07-06 09:49:27 +0530] [4091254] [INFO] Worker exiting (pid: 4091254)
[2022-07-06 09:49:27 +0530] [4091255] [INFO] Booting worker with pid: 4091255
[2022-07-06 09:49:27 +0530] [4091256] [INFO] Booting worker with pid: 4091256
[2022-07-06 09:49:27 +0530] [4091255] [ERROR] Exception in worker process
Traceback (most recent call last):
  File "/root/anaconda3/envs/fastapi/lib/python3.10/site-packages/gunicorn/arbiter.py", line 589, in spawn_worker
    worker.init_process()
  File "/root/anaconda3/envs/fastapi/lib/python3.10/site-packages/uvicorn/workers.py", line 66, in init_process
    super(UvicornWorker, self).init_process()
  File "/root/anaconda3/envs/fastapi/lib/python3.10/site-packages/gunicorn/workers/base.py", line 134, in init_process
    self.load_wsgi()
  File "/root/anaconda3/envs/fastapi/lib/python3.10/site-packages/gunicorn/workers/base.py", line 146, in load_wsgi
    self.wsgi = self.app.wsgi()
  File "/root/anaconda3/envs/fastapi/lib/python3.10/site-packages/gunicorn/app/base.py", line 67, in wsgi
    self.callable = self.load()
  File "/root/anaconda3/envs/fastapi/lib/python3.10/site-packages/gunicorn/app/wsgiapp.py", line 58, in load
    return self.load_wsgiapp()
  File "/root/anaconda3/envs/fastapi/lib/python3.10/site-packages/gunicorn/app/wsgiapp.py", line 48, in load_wsgiapp
    return util.import_app(self.app_uri)
  File "/root/anaconda3/envs/fastapi/lib/python3.10/site-packages/gunicorn/util.py", line 359, in import_app
    mod = importlib.import_module(module)
  File "/root/anaconda3/envs/fastapi/lib/python3.10/importlib/__init__.py", line 126, in import_module
    return _bootstrap._gcd_import(name[level:], package, level)
  File "<frozen importlib._bootstrap>", line 1050, in _gcd_import
  File "<frozen importlib._bootstrap>", line 1027, in _find_and_load
  File "<frozen importlib._bootstrap>", line 1004, in _find_and_load_unlocked
ModuleNotFoundError: No module named 'app'
[2022-07-06 09:49:27 +0530] [4091255] [INFO] Worker exiting (pid: 4091255)
[2022-07-06 09:49:27 +0530] [4091256] [ERROR] Exception in worker process
Traceback (most recent call last):
  File "/root/anaconda3/envs/fastapi/lib/python3.10/site-packages/gunicorn/arbiter.py", line 589, in spawn_worker
    worker.init_process()
  File "/root/anaconda3/envs/fastapi/lib/python3.10/site-packages/uvicorn/workers.py", line 66, in init_process
    super(UvicornWorker, self).init_process()
  File "/root/anaconda3/envs/fastapi/lib/python3.10/site-packages/gunicorn/workers/base.py", line 134, in init_process
    self.load_wsgi()
  File "/root/anaconda3/envs/fastapi/lib/python3.10/site-packages/gunicorn/workers/base.py", line 146, in load_wsgi
    self.wsgi = self.app.wsgi()
  File "/root/anaconda3/envs/fastapi/lib/python3.10/site-packages/gunicorn/app/base.py", line 67, in wsgi
    self.callable = self.load()
  File "/root/anaconda3/envs/fastapi/lib/python3.10/site-packages/gunicorn/app/wsgiapp.py", line 58, in load
    return self.load_wsgiapp()
  File "/root/anaconda3/envs/fastapi/lib/python3.10/site-packages/gunicorn/app/wsgiapp.py", line 48, in load_wsgiapp
    return util.import_app(self.app_uri)
  File "/root/anaconda3/envs/fastapi/lib/python3.10/site-packages/gunicorn/util.py", line 359, in import_app
    mod = importlib.import_module(module)
  File "/root/anaconda3/envs/fastapi/lib/python3.10/importlib/__init__.py", line 126, in import_module
    return _bootstrap._gcd_import(name[level:], package, level)
  File "<frozen importlib._bootstrap>", line 1050, in _gcd_import
  File "<frozen importlib._bootstrap>", line 1027, in _find_and_load
  File "<frozen importlib._bootstrap>", line 1004, in _find_and_load_unlocked
ModuleNotFoundError: No module named 'app'
[2022-07-06 09:49:27 +0530] [4091256] [INFO] Worker exiting (pid: 4091256)
[2022-07-06 09:49:27 +0530] [4091257] [INFO] Booting worker with pid: 4091257
[2022-07-06 09:49:27 +0530] [4091257] [ERROR] Exception in worker process
Traceback (most recent call last):
  File "/root/anaconda3/envs/fastapi/lib/python3.10/site-packages/gunicorn/arbiter.py", line 589, in spawn_worker
    worker.init_process()
  File "/root/anaconda3/envs/fastapi/lib/python3.10/site-packages/uvicorn/workers.py", line 66, in init_process
    super(UvicornWorker, self).init_process()
  File "/root/anaconda3/envs/fastapi/lib/python3.10/site-packages/gunicorn/workers/base.py", line 134, in init_process
    self.load_wsgi()
  File "/root/anaconda3/envs/fastapi/lib/python3.10/site-packages/gunicorn/workers/base.py", line 146, in load_wsgi
    self.wsgi = self.app.wsgi()
  File "/root/anaconda3/envs/fastapi/lib/python3.10/site-packages/gunicorn/app/base.py", line 67, in wsgi
    self.callable = self.load()
  File "/root/anaconda3/envs/fastapi/lib/python3.10/site-packages/gunicorn/app/wsgiapp.py", line 58, in load
    return self.load_wsgiapp()
  File "/root/anaconda3/envs/fastapi/lib/python3.10/site-packages/gunicorn/app/wsgiapp.py", line 48, in load_wsgiapp
    return util.import_app(self.app_uri)
  File "/root/anaconda3/envs/fastapi/lib/python3.10/site-packages/gunicorn/util.py", line 359, in import_app
    mod = importlib.import_module(module)
  File "/root/anaconda3/envs/fastapi/lib/python3.10/importlib/__init__.py", line 126, in import_module
    return _bootstrap._gcd_import(name[level:], package, level)
  File "<frozen importlib._bootstrap>", line 1050, in _gcd_import
  File "<frozen importlib._bootstrap>", line 1027, in _find_and_load
  File "<frozen importlib._bootstrap>", line 1004, in _find_and_load_unlocked
ModuleNotFoundError: No module named 'app'
[2022-07-06 09:49:27 +0530] [4091257] [INFO] Worker exiting (pid: 4091257)
[2022-07-06 09:49:27 +0530] [4091245] [WARNING] Worker with pid 4091257 was terminated due to signal 15
[2022-07-06 09:49:27 +0530] [4091245] [WARNING] Worker with pid 4091256 was terminated due to signal 15
[2022-07-06 09:49:27 +0530] [4091245] [WARNING] Worker with pid 4091255 was terminated due to signal 15
[2022-07-06 09:49:28 +0530] [4091245] [INFO] Shutting down: Master
[2022-07-06 09:49:28 +0530] [4091245] [INFO] Reason: Worker failed to boot.
